# 18.5.3 Task和协程

## 18.5.3.1 协程

协程有两个不同但相关的概念:

1. 携程函数:
   使用async def 或者 @asyncio.coroutine装饰的函数定义;

2. 协程对象:
   通过协程函数获得的对象，此对象表示最终完成的计算或I/O操作;

协程可以做的事情:

* result = await future 或者 result = yield from future 
  挂起协程直到futures完成，然后返回future的结果，或者抛出一个异常，两者都将传播
  
* result = await coroutine or result = yield from coroutine
  等待另一个协程生产结果，coroutine表达式必须是到另一个协程的调用. 

* return expression 
  通过await或者yield from 来等待当前协程结果的协程生成一个结果.

* raise exception
  为通过await 或者 yield from 来等待当前协程结果的协程抛出一个异常.

调用协程不会运行协程代码，运行协程代码有两种基本方法:

* 调用 await coroutine 或者 yield from coroutine 

* 使用 ensure_future函数或者AbstractEventLoop.create_task()方法调度执行.

协程(和任务)只能在已经运行事件循环中执行;

### 18.5.3.1.1 示例: Hello World 协程

```python
import asyncio

async def hello_world():
	print('Hello World!')

loop = asyncio.get_event_loop()
loop.run_until_complete(hello_world())
loop.close()
```

### 18.5.3.1.2 示例: 显示当前日期的协程

```python
import asyncio
import datetime

async def display_date(loop):
	end_time = loop.time() + 5.0
	while True:
		print(datetime.datetime.now())
		if (loop.time() + 1.0) >= end_time:
			break
		await asyncio.sleep(1)

loop = asyncio.get_event_loop()
loop.run_until_complete(display_date(loop))
loop.close()
```

### 18.5.3.1.3 示例: 链接协程

```python
import asyncio

async def compute(x, y):
	print('Compute %s + %s...' % (x, y))
	await asyncio.sleep(1.0)
	return x + y

async def print_sum(x, y):
	result = await compute(x, y)
	print('%s + %s = %s' % (x, y, result))

loop = asyncio.get_event_loop()
loop.run_until_complete(print_sum(1, 2))
loop.close()
```

## 18.5.3.4 Future

```text
class asyncio.Future(*, loop=None)
	此类几乎和concurrent.futures.Future兼容
	区别:
		1. result() 和 exception() 不需要超时参数, 当future不再需要他们的时候
		会抛出一个异常。
		2. 始终通过事件循环的call_soon_threadsafe() 调用通过add_done_callback()
		注册的回调。

	此类为非线程安全类;

	cancel()
		取消future并安排回调。
		如果future已经完成或取消，返回False, 否则，将future的状态更改为'已取消',
		安排回调并返回True.

	cancelled()
		如果未被取消，返回True

	done()
		如果future完成了，返回Ture, 完成意味着result/except可用，或future被取消.
	
	result()
		返回这个future所代表的结果.如果future已取消，则引发CancelledError异常，
		如果future的结果尚不可用，则引发InvalidStateError;

	exception()
		返回在future设置的异常.
		同样会引发CancelledError, InvalidStateError异常.

	add_done_callback(fn)
		添加回调以便在future完成时运行。回调使用单个参数调用--future对象。
		如果future在调用时已经完成，则使用call_soon()计划回调.
	
	remove_done_callback(fn)
		从'调用完成时'列表中删除回调的所有实例,返回已删除的回调数量.
	
	set_result(result)
		标记未来完成并设置其结果，如果调用此方法时future已经完成，
		则引发InvalidStateError.

	set_exception(exception)
		标记future完成并设置异常
		如果调用此方法时future已经完成，则引发InvalidStateError.
```

### 18.5.3.4.1 示例: 使用run_until_complete()的期物

组合Future 和 coroutine function的示例:

```python
import asyncio

@asyncio.coroutine
def slow_operation(future):
	yield from asyncio.sleep(1)
	future.set_result('Future is done!')

loop = asyncio.get_event_loop()
future = asyncio.Future()
asyncio.ensure_future(slow_operation(future))
loop.run_until_complete(future)
print(future.result())
loop.close()
```
协程函数负责计算，并将结果存储到future，run_until_complete()方法等待future完成.

### 18.5.3.2 示例: 使用 run_forever() 的future

```python
import asyncio

@asyncio.coroutine
def slow_operation(future):
	yield from asyncio.sleep(1)
	future.set_result('Future is done!')

def got_result(future):
	print(future.result())
	loop.stop()

loop = asyncio.get_event_loop()
future = asyncio.Future()
asyncio.ensure_future(slow_operation(future))
future.add_done_callback(got_result)
try:
	loop.run_forever()
finally:
	loop.close()
```
future将slow_operation和got_result链接到一起: 当slow_operation完成时，
got_result()与结果一起调用。

## 18.5.3.5 Task

```text
class asyncio.Task(coro, *, loop=None)
	调度协程的执行: 封装成future, task就是Future的子类.
	task负责在事件循环中执行协程对象。如果包装好的协程从future产生, task
	将暂停包装的协程的执行，并等待future的完成。当完成future时，包装的协程
	程序的执行将以future的结果或异常重新启动。

    事件循环使用协程调度:事件循环一次只运行一个task。如果其他事件循环
	在不同的线程中运行，则其他task可能并行运行。当一个任务等待future的完成时,
	事件循环执行一个新任务。

	task的取消和future的取消不同, 调用 cancel() 将抛出CancelledError给协程，
	cancelled()仅在包装的协程没有捕获CancelledError异常或引发CancelledError
	异常时才返回True。

	不要直接创建Task实例: 使用ensure_future或者AbstractEventLoop.create_task
	同样，此类为非线程安全类.

	classmethod all_tasks(loop=None)
		返回一组事件循环的所有任务，默认清空下，返回当前事件循环的所有任务。
	classmethod current_task(loop=None)
		返回事件循环中当前正在运行的task, 或者返回None
	cancel()
		请求取消task
		将在下一个循环中抛出CancelledError,
		与Future.cancel()不同，这个不能保证task将被取消，异常可能被处理了;
```

### 18.5.3.5.1 示例: 并行执行任务

并行执行3个任务(A, B, C)的示例:
```pythhon
import asyncio

@asyncio.coroutine
def factorial(name, number):
	f = 1
	for i in range(2, number+1):
		print('Task %s: Compute factorial(%s)...' % (name, i))
		yield from asyncio.sleep(1)
		f *= i
	print('Task %s: factorial(%s) = %s' % (name, number, f))

loop = asyncio.get_event_loop()
tasks = [
	asyncio.ensure_future(factorial('A', 2)),
	asyncio.ensure_future(factorial('B', 3)),
	asyncio.ensure_future(factorial('C', 4))
]
loop.run_until_complete(asyncio.gather(*tasks))
loop.close()
```

## 18.5.3.6 任务函数

```text
asyncio.as_completed(fs, *, loop=None, timeout=None)
	当完成等待后，返回一个迭代器，迭代器的对象是Future;
	如果在所有的Futures完成前超时，则抛出asyncio.TimeoutError

asyncio.ensure_future(coro_or_future, *, loop=None)
	调度执行一个协程对象，并且把它封装成future, 返回task对象
	如果参数是Future, 则直接返回.

asyncio.gather(*coros_or_futures, loop=None, return_exceptions=False)
	从这个协程或者futures对象,返回future结果集；
	所有的future必须是同一个事件循环中的；如果所有任务都完成了，则返回
	的future的结果是一个列表，结果列表的顺序是安装原始序列的顺序，不一定
	是完成结果的顺序；

	如果 return_exceptions=True,则任务中的异常将收集到结果列表中, 否则，
	第一个引发的异常将会立即传递到future中;

asyncio.iscoroutine(obj)
	如果obj是协程对象，返回True

asyncio.iscoroutinefunction(func)
	如果func是协程函数，则返回True

asyncio.run_coroutine_threadsafe(coro, loop)
	将coro协程提交给loop事件循环。
	返回concurrent.futures.Future, 以便访问结果.
	主要处理不同线程中使用事件循环;

coroutine asyncio.sleep(delay, result=None, *, loop=None)
	创建一个在给定时间(单位: 秒)后完成的协程.
	如果提供result，则当协程完成时，将生产给调用者.

asyncio.shield(arg, *, loop=None)
	给future提供一个保护，防止被取消, 执行完future之后在执行取消任务;

coroutine asyncio.wait(futures, *, loop=None, timeout=None, 
					   return_when=ALL_COMPLETED)
	等待futures完成，futures是Futures和协程对象，协程被包裹在task中,返回
	含有两个集合的Future: (done, pending), 即完成的和没有完成的.
	futures不能为空，timeout用于控制返回前等待的最大秒数，timeout可以是int
	或者float,如果timeout=None或者没有给出，则无限等待.
	return_when: 此函数什么情况下返回，它必须是concurrent.futures模块的常量:

	1. FIRST_COMPLETED: 只要有future呗完成或被取消就返回
	2. FIRST_EXCEPTION: 只要有future抛出异常就返回，如果没有发生异常就等效于
	ALL_COMPLETED的情况。
	3. ALL_COMPLETED: 当所有future都被完成或取消，该函数才返回

	此函数是一个协程;
	用法:
	done, pending = await asyncio.wait(fs)

coroutine asyncio.wait_for(fut, timeout, *, loop=None)
	等待单个future或者协程对象完成或者超时，如果timeout等于None，则一直等待。
	返回future或协程的结果，当超时发生时，任务会被取消，并引发
	asyncio.TimeoutError. 将其封装在shield()中，如果等待被取消，future也会
	被取消。
	用法:
	result = await asyncio.wait_for(fut, 60, 0)
```




